Workbook

Sheet CCA
C5: Principais características dos instrumentos que compõem o Patrimônio de Referência (PR)
C7: Valores em R$
C8: 1 | D8: Emissor | E8: NU FINANCEIRA S.A. – SOCIEDADE DE CRÉDITO, FINANCIAMENTO E INVESTIMENTO | F8: NU FINANCEIRA S.A. – SOCIEDADE DE CRÉDITO, FINANCIAMENTO E INVESTIMENTO | G8: NU FINANCEIRA S.A. – SOCIEDADE DE CRÉDITO, FINANCIAMENTO E INVESTIMENTO
C9: 2 | D9: Identificador único | E9: LFSN1900844 | F9: LFSN22008CB | G9: BRNUFNLFI039
C10: 3 | D10: Lei aplicável ao instrumento | E10: Lei nº 12.249, de 11 de junho de 2010 |Resolução nº 4.123, de 23 de agosto de 2012, do Conselho Monetário Nacional | Resolução nº 4.192, de 1º de março de 2013, do CMN | Lei nº 6.385, de 7 de dezembro de 1976 | Instrução CVM nº 476, de 16 de janeiro de 2009 | F10: Lei nº 12.249, de 11 de junho de 2010 |Resolução nº 4.123, de 23 de agosto de 2012, do Conselho Monetário Nacional | Resolução nº 4.192, de 1º de março de 2013, do CMN | Lei nº 6.385, de 7 de dezembro de 1976 | Instrução CVM nº 476, de 16 de janeiro de 2009 | G10: Lei nº 12.249, de 11 de junho de 2010 |Resolução nº 4.123, de 23 de agosto de 2012, do Conselho Monetário Nacional | Resolução nº 4.192, de 1º de março de 2013, do CMN | Lei nº 6.385, de 7 de dezembro de 1976 | Instrução CVM nº 476, de 16 de janeiro de 2009
C11: 4 | D11: Classificação do instrumento como componente do PR durante o tratamento temporário de que trata o art. 28 da Resolução nº 4.192, de 2013. | E11: NA | F11: NA | G11: NA
C12: 5 | D12: Classificação do instrumento como componente do PR após o tratamento temporário de que trata a linha anterior | E12: Nível II | F12: Nível II | G12: Nível I
C13: 6 | D13: Escopo da elegibilidade do instrumento | E13: Conglomerado | F13: Conglomerado | G13: Conglomerado
C14: 7 | D14: Tipo de instrumento | E14: Letra Financeira | F14: Letra Financeira | G14: Letra Financeira
C15: 8 | D15: Valor reconhecido no PR | E15: 1.1487324e+08 | F15: 8.6671605e+08 | G15: 7.1888604e+08
C16: 9 | D16: Valor de face do instrumento | E16: 75000000 | F16: 800000000 | G16: 700000000
C17: 10 | D17: Classificação contábil | E17: Passivo – custo amortizado | F17: Passivo – custo amortizado | G17: Passivo – custo amortizado
C18: 11 | D18: Data original de emissão | E18: 14/06/19 | F18: 17/06/22 | G18: 31/10/22
C19: 12 | D19: Perpétuo ou com vencimento | E19: Com vencimento | F19: Com vencimento | G19: Perpétuo
C20: 13 | D20: Data original de vencimento | E20: 14/06/29 | F20: 17/06/32 | G20: NA
C21: 14 | D21: Opção de resgate ou recompra | E21: Sim | F21: Sim | G21: Sim
C22: 15 | D22: (1) Data de resgate ou de recompra (2) Datas de resgate ou de recompra condicionadas (3) Valor de resgate ou de recompra | E22: 14/06/24 | F22: 17/06/27 | G22: 46753
C23: 16 | D23: Datas de resgate ou de recompra subsequentes, se aplicável | E23: Resgate ou recompra pode ocorrer a partir 14/06/2024 | F23: Resgate ou recompra pode ocorrer a partir 17/06/2027 | G23: Resgate ou recompra pode ocorrer a partir 01/01/2028
C24: Remuneração/Dividendos
C25: 17 | D25: Remuneração ou dividendos fixos ou variáveis | E25: Fixo | F25: Fixo | G25: Fixo
C26: 18 | D26: Taxa de remuneração e índice referenciado | E26: 12,8% | F26: 16,0% | G26: 17,32%
C27: 19 | D27: Possibilidade de suspensão de pagamento de dividendos | E27: Não | F27: Não | G27: Não
C28: 20 | D28: Completa discricionariedade, discricionariedade parcial ou mandatória | E28: Mandatório | F28: Mandatório | G28: Mandatório
C29: 21 | D29: Existência de cláusulas que alterem prazos ou condições de remuneração pactuados ou outro incentivo para resgate | E29: Não | F29: Não | G29: Não
C30: 22 | D30: Cumulativo ou não cumulativo | E30: NA | F30: NA | G30: NA
C31: 23 | D31: Conversível ou não conversível | E31: Não conversível | F31: Não conversível | G31: Não conversível
C32: 24 | D32: Se conversível, em quais situações | E32: NA | F32: NA | G32: NA
C33: 25 | D33: Se conversível, totalmente ou parcialmente | E33: NA | F33: NA | G33: NA
C34: 26 | D34: Se conversível, taxa de conversão | E34: NA | F34: NA | G34: NA
C35: 27 | D35: Se conversível, conversão obrigatória ou opcional | E35: NA | F35: NA | G35: NA
C36: 28 | D36: Se conversível, especificar para qual tipo de instrumento | E36: NA | F36: NA | G36: NA
... C45: 37 | D45: Se sim, especificar as características de que trata a linha anterior | E45: NA | F45: NA | G45: NA

Sheet CC1
C5: Composição do Patrimônio de Referência - PR [CC1] | E5: Dec-2022
E6: a | F6: b
C7: Valores em R$ | E7: Valor | F7: Referência no balanço do conglomerado
C8: Capital Principal: instrumentos e reservas
C9: 1 | D9: Instrumentos elegíveis ao Capital Principal | E9: 4.0084046e+09 | F9: (a)
C10: 2 | D10: Reservas de lucros | E10: 1.4069492e+09 | F10: (b)
C11: 3 | D11: Outras receitas e outras reservas | E11: 87924176 | F11: (c)
C12: 5 | D12: Participação de não controladores nos instrumentos emitidos por subsidiárias do conglomerado prudencial e elegíveis ao seu Capital Principal | E12: -
C13: 6 | D13: Capital Principal antes dos ajustes prudenciais | E13: 5.5032779e+09 | F13: (d)
C14: Capital Principal: ajustes prudenciais
C15: 7 | D15: Ajustes prudenciais relativos a apreçamentos de instrumentos financeiros (PVA) | E15: -
C16: 8 | D16: Ágios pagos na aquisição de investimentos com fundamento em expectativa de rentabilidade futura | E16: 1.054082e+09
C17: 9 | D17: Ativos intangíveis | E17: 2.97501e+08
C18: 10 | D18: Créditos tributários decorrentes de prejuízos fiscais e de base negativa de Contribuição Social sobre o Lucro Líquido e os originados dessa contribuição relativos a períodos de apuração encerrados até 31 de dezembro de 1998 | E18: 87690035
C19: 11 | D19: Ajustes relativos ao valor de mercado dos instrumentos financeiros derivativos utilizados para hedge de fluxo de caixa de itens protegidos cujos ajustes de marcação a mercado não são registrados contabilmente | E19: -
C20: 15 | D20: Ativos atuariais relacionados a fundos de pensão de benefício definido | E20: -
C21: 16 | D21: Ações ou outros instrumentos de emissão própria autorizados a compor o Capital Principal da instituição ou conglomerado, adquiridos diretamente, indiretamente ou de forma sintética | E21: -
C22: 17 | D22: Valor total das deduções relativas às aquisições recíprocas de Capital Principal | E22: -
C23: 18 | D23: Valor total das deduções relativas às participações líquidas não significativas em Capital Principal de instituições autorizadas a funcionar pelo Banco Central do Brasil e de instituições financeiras no exterior não consolidadas e em capital social de empresas assemelhadas a instituições financeiras não consolidadas, sociedades seguradoras, resseguradoras, de capitalização e entidades abertas de previdência complementar | E23: -
C24: 19 | D24: Valor total das deduções relativas às participações líquidas significativas em Capital Principal de instituições autorizadas a funcionar pelo Banco Central do Brasil e de instituições financeiras no exterior não consolidadas e em capital social de empresas assemelhadas a instituições financeiras não consolidadas, sociedades seguradoras, resseguradoras, de capitalização e entidades abertas de previdência complementar, que exceda 10% do valor do Capital Principal da própria instituição ou conglomerado, desconsiderando deduções específicas | E24: -
C25: 21 | D25: Valor total das deduções relativas aos créditos tributários decorrentes de diferenças temporárias que dependam de geração de lucros ou receitas tributáveis futuras para sua realização, que exceda 10% do Capital Principal da própria instituição ou conglomerado, desconsiderando deduções específicas | E25: -
C26: 22 | D26: Valor que excede, de forma agregada, 15% do Capital Principal da própria instituição ou conglomerado | E26: -
C27: 23 | D27: do qual: oriundo de participações líquidas significativas em Capital Principal de instituições autorizadas a funcionar pelo Banco Central do Brasil e de instituições financeiras no exterior não consolidadas e em capital social de empresas assemelhadas a instituições financeiras não consolidadas, de sociedades seguradoras, resseguradoras, de capitalização e de entidades abertas de previdência complementar | E27: -
C28: 25 | D28: do qual: oriundo de créditos tributários decorrentes de diferenças temporárias que dependam de geração de lucros ou receitas tributáveis futuras para sua realização | E28: -
C29: 26 | D29: Ajustes regulatórios nacionais | E29: -
C30: 26.a | D30: Ativos permanentes diferidos | E30: -
... C39: 27 | D39: Dedução aplicada ao Capital Principal decorrente de insuficiência de Capital Complementar e de Nível II para cobrir as respectivas deduções nesses componentes | E39: -
C40: 28 | D40: Total de deduções regulatórias ao Capital Principal | E40: 1.4392731e+09
C41: 29 | D41: Capital Principal | E41: 4.0640049e+09
C42: Capital Complementar: instrumentos
C43: 30 | D43: Instrumentos elegíveis ao Capital Complementar | E43: 7.1888604e+08
C44: 31 | D44: dos quais: classificados como capital social conforme as regras contábeis | E44: -
C45: 32 | D45: dos quais: classificados como passivo conforme as regras contábeis | E45: 7.1888604e+08
C46: 34 | D46: Participação de não controladores nos instrumentos emitidos por subsidiárias da instituição ou conglomerado e elegíveis ao seu Capital Complementar | E46: -
C47: 36 | D47: Capital Complementar antes das deduções regulatórias | E47: 7.1888604e+08
C48: Capital Complementar: deduções regulatórias
C49: 37 | D49: Ações ou outros instrumentos de emissão própria autorizados a compor o Capital Complementar da instituição ou conglomerado, adquiridos diretamente, indiretamente ou de forma sintética | E49: -
C50: 38 | D50: Valor total das deduções relativas às aquisições recíprocas de Capital Complementar | E50: -
C51: 39 | D51: Valor total das deduções relativas aos investimentos líquidos não significativos em Capital Complementar de instituições autorizadas a funcionar pelo Banco Central do Brasil e de instituições financeiras no exterior não consolidadas | E51: -
C52: 40 | D52: Valor total das deduções relativas aos investimentos líquidos significativos em Capital Complementar de instituições autorizadas a funcionar pelo Banco Central do Brasil e de instituições financeiras no exterior não consolidadas | E52: -
...

Sheet CC2
C5: Conciliação do Patrimônio de Referência (PR) com o balanço patrimonial | E5: Dec-22
E6: a | F6: b | G6: c
C7: Valores em R$ | E7: Valores do balanço patrimonial no final do período | F7: Valores considerados para fins da regulamentação prudencial no final do período | G7: Referência no balanço do conglomerado
C8: Ativo
C9: 1 | D9: Caixa e equivalentes a caixa | E9: 35752146 | F9: 35752146
D10: Aplicações interfinanceiras de liquidez | E10: 3.1399741e+08 | F10: 3.1399741e+08
C11: 2 | D11: Instrumentos financeiros | E11: 7.2183535e+10 | F11: 7.2183535e+10
D12: Operações de crédito | E12: 2.0058592e+10 | F12: 2.0058592e+10
C13: 3 | D13: Operações de arrendamento mercantil | E13: - | F13: -
C14: 4 | D14: Provisões para perdas esperadas associadas ao risco de crédito | E14: -5.7838668e+09 | F14: -5.7838668e+09
C15: 5 | D15: Ativos Fiscais | E15: 2.2829266e+09 | F15: 2.2829266e+09
D16: Corrente | E16: - | F16: -
D17: Diferido | E17: 2.2829266e+09 | F17: 2.2829266e+09
C18: 6 | D18: Investimentos em participações em coligadas e controladas | E18: 1.0609776e+08 | F18: 1.0609776e+08
D19: Ágio baseado em expectativa de rentabilidade futura | E19: - | F19: -
D20: Participação em instituições financeiras | E20: - | F20: -
D21: Outros | E21: 1.0609776e+08 | F21: 1.0609776e+08
C22: 7 | D22: Imobilizado de uso | E22: 23475656 | F22: 23475656
C23: 8 | D23: Intangível | E23: 1.7565797e+09 | F23: 1.7565797e+09
C24: 9 | D24: Depreciações e amortizações | E24: -4.0640489e+08 | F24: -4.0640489e+08
C25: 10 | D25: Provisões para redução ao valor recuperável de ativos | E25: - | F25: -
D26: Outros créditos | E26: 7.0473632e+09 | F26: 7.0473632e+09
C27: 11 | D27: Total de ativos | E27: 9.7618048e+10 | F27: 9.7618048e+10
C28: Passivo
C29: 12 | D29: Depósitos e demais instrumentos financeiros | E29: 8.2208984e+10 | F29: 8.2208984e+10
C30: 13 | D30: Provisões | E30: 607218.56 | F30: 607218.56
C31: 14 | D31: Obrigações fiscais | E31: 2.5271443e+09 | F31: 2.5271443e+09
D32: Corrente | E32: 2.4981526e+09 | F32: 2.4981526e+09
D33: Diferida | E33: 28991690 | F33: 28991690
D34: Outras obrigações | E34: 7.3780342e+09 | F34: 7.3780342e+09
C35: 15 | D35: Total de passivos | E35: 9.211477e+10 | F35: 9.211477e+10
C36: Patrimônio líquido
C37: 16 | D37: Capital social realizado [Capital social] | E37: 4.0084046e+09 | F37: 4.0084046e+09 | G37: (a)
C38: 17 | D38: do qual: montante elegível para Capital Principal | E38: 4.0084046e+09 | F38: 4.0084046e+09
C39: 18 | D39: do qual: montante elegível para Capital Complementar | E39: - | F39: -
C40: 19 | D40: Reserva de lucros | E40: 1.4069492e+09 | F40: 1.4069492e+09 | G40: (b)
C41: 20 | D41: Outros resultados abrangentes | E41: 87924176 | F41: 87924176 | G41: (c)
C42: 21 | D42: Lucros ou prejuízos acumulados | E42: - | F42: -
C43: 22 | D43: Ações em tesouraria | E43: - | F43: -
C44: 23 | D44: Patrimônio líquido total | E44: 5.5032779e+09 | F44: 5.5032779e+09 | G44: (d)
...

Sheet KM1
C5: Informações qualitativas sobre os requerimentos prudenciais [KM1]
E6: a | F6: b | G6: c | H6: d | I6: e
C7: Valores em R$ | E7: Dec-22 | F7: Sep-22 | G7: Jun-22 | H7: Mar-22 | I7: Dec-21
C8: Capital regulamentar - valores
C9: 1 | D9: Capital Principal | E9: 4.0640049e+09 | F9: 3.3468715e+09 | G9: 3.1094263e+09 | H9: 2.8861858e+09 | I9: 2.6051538e+09
C10: 2 | D10: Nível I | E10: 4.7828909e+09 | F10: 3.3468715e+09 | G10: 3.1094263e+09 | H10: 2.8861858e+09 | I10: 2.6051538e+09
C11: 3 | D11: Patrimônio de Referência (PR) | E11: 5.7644802e+09 | F11: 4.2940285e+09 | G11: 4.0217858e+09 | H11: 2.9911369e+09 | I11: 2.7070405e+09
C12: 3b | D12: Excesso dos recursos aplicados no ativo permanente | E12: - | F12: - | G12: - | H12: - | I12: -
C13: 3c | D13: Destaque do PR | E13: - | F13: - | G13: - | H13: - | I13: -
C14: Ativos ponderados pelo risco (RWA) - valores
C15: 4 | D15: RWA total | E15: 2.6963627e+10 | F15: 2.422015e+10 | G15: 1.8590678e+10 | H15: 1.6493485e+10 | I15: 1.1957297e+10
C16: Capital regulamentar como proporção do RWA
C17: 5 | D17: Índice de Capital Principal (ICP) | E17: 0.1507 | F17: 0.1382 | G17: 0.1673 | H17: 0.175 | I17: 0.2179
C18: 6 | D18: Índice de Nível 1 (%) | E18: 0.1774 | F18: 0.1382 | G18: 0.1673 | H18: 0.175 | I18: 0.2179
C19: 7 | D19: Índice de Basileia | E19: 0.2138 | F19: 0.1773 | G19: 0.2163 | H19: 0.1814 | I19: 0.2264
C20: Adicional de Capital Principal (ACP) como proporção do RWA
C21: 8 | D21: Adicional de Conservação de Capital Principal - ACPConservação (%) | E21: 0.025 | F21: 0.025 | G21: 0.025 | H21: 0.02 | I21: 0.02
C22: 9 | D22: Adicional Contracíclico de Capital Principal - ACPContracíclico (%) | E22: 0 | F22: 0 | G22: 0 | H22: 0 | I22: 0
C23: 10 | D23: Adicional de Importância Sistêmica de Capital Principal - ACPSistêmico (%) | E23: 0 | F23: 0 | G23: 0 | H23: 0 | I23: 0
C24: 11 | D24: ACP total (%) | E24: 0.025 | F24: 0.025 | G24: 0.025 | H24: 0.02 | I24: 0.02
C25: 12 | D25: Margem excedente de Capital Principal (%) | E25: 0.0807 | F25: 0.0682 | G25: 0.0973 | H25: 0.11 | I25: 0.1529
C26: Razão de Alavancagem (RA)
C27: 13 | D27: Exposição total | E27: NA | F27: NA | G27: NA | H27: NA | I27: NA
C28: 14 | D28: RA (%) | E28: NA | F28: NA | G28: NA | H28: NA | I28: NA
C29: Indicador Liquidez de Curto Prazo (LCR)
C30: 15 | D30: Total de Ativos de Alta Liquidez (HQLA) | E30: NA | F30: NA | G30: NA | H30: NA | I30: NA
C31: 16 | D31: Total de saídas líquidas de caixa | E31: NA | F31: NA | G31: NA | H31: NA | I31: NA
C32: 17 | D32: LCR (%) | E32: NA | F32: NA | G32: NA | H32: NA | I32: NA
C33: Indicador de Liquidez de Longo Prazo (NSFR)
C34: 18 | D34: Recursos estáveis disponíveis (ASF) | E34: NA | F34: NA | G34: NA | H34: NA | I34: NA
C35: 19 | D35: Recursos estáveis requeridos (RSF) | E35: NA | F35: NA | G35: NA | H35: NA | I35: NA
C36: 20 | D36: NSFR (%) | E36: NA | F36: NA | G36: NA | H36: NA | I36: NA
C38: Comentários

Sheet OV1
C5: Informações quantitativas sobre os requerimentos prudenciais [OV1] | E5: a | F5: b | G5: c
E6: RWA | G6: Requerimento mínimo de PR
C7: Valores em R$ | E7: 44917 | F7: 44826 | G7: 44917
C8: 0 | D8: Risco de Crédito - tratamento mediante abordagem padronizada | E8: 2.0903895e+10 | F8: 1.823766e+10 | G8: 1.6723116e+09
C9: 2 | D9: Risco de crédito em sentido estrito | E9: 1.9656675e+10 | F9: 1.7068361e+10 | G9: 1.572534e+09
C10: 6 | D10: Risco de crédito de contraparte (CCR) | E10: 4171514.5 | F10: 463631.08 | G10: 333721.16
C11: 7 | D11: Do qual: mediante abordagem padronizada para risco de crédito de contraparte (SA-CCR) | E11: - | F11: - | G11: -
C12: 7a | D12: Do qual: mediante uso da abordagem CEM | E12: 4171514.5 | F12: 463631.08 | G12: 333721.16
C13: 9 | D13: Do qual: mediante demais abordagens | E13: - | F13: - | G13: -
C14: 10 | D14: Acréscimo relativo ao ajuste associado à variação do valor dos derivativos em decorrência de variação da qualidade creditícia da contraparte (CVA) | E14: 658762.35 | F14: 1068953.2 | G14: 52700.99
C15: 12 | D15: Cotas de fundos não consolidados - ativos subjacentes identificados | E15: 1.698977e+08 | F15: 90431817 | G15: 13591816
C16: 13 | D16: Cotas de fundos não consolidados - ativos subjacentes inferidos conforme regulamento do fundo | E16: 8217582.1 | F16: 6366637 | G16: 657406.57
C17: 14 | D17: Cotas de fundos não consolidados - ativos subjacentes não identificados | E17: - | F17: - | G17: -
C18: 16 | D18: Exposições de securitização - requerimento calculado mediante abordagem padronizada | E18: 6.3235551e+08 | F18: 7.6184521e+08 | G18: 50588441
C19: 25 | D19: Valores referentes às exposições não deduzidas no cálculo do PR | E19: 4.3191928e+08 | F19: 3.0912313e+08 | G19: 34553542
C20: 20 | D20: Risco de mercado | E20: 3.7046848e+08 | F20: 2.9322652e+08 | G20: 29637478
C21: 21 | D21: Do qual: requerimento calculado mediante abordagem padronizada (RWAMPAD) | E21: 3.7046848e+08 | F21: 2.9322652e+08 | G21: 29637478
C22: 22 | D22: Do qual: requerimento calculado mediante modelo interno (RWAMINT)
C23: 24 | D23: Risco operacional | E23: 5.6892634e+09 | F23: 5.6892634e+09 | G23: 4.5514107e+08
C24: 27 | D24: Total (2+6+10+12+13+14+16+25+20+24) | E24: 2.6963627e+10 | F24: 2.3726674e+10 | G24: 2.1570902e+09
C26: Comentários

Sheet MR1
C5: Abordagem padronizada - fatores de risco associados ao risco de mercado [MR1] | E5: a
E6: RWAMPAD
C7: Valores em R$ | E7: 44917
C8: 1 | D8: Taxas de juros | E8: 271544319
C9: 1a | D9: Taxas de juros prefixada denominadas em Real (RWAJUR1) | E9: 12322854
C10: 1b | D10: Taxas dos cupons de moeda estrangeira (RWAJUR2) | E10: 0
C11: 1c | D11: Taxas dos cupons de índices de preço (RWAJUR3) | E11: 2.5922147e+08
C12: 1d | D12: Taxas dos cupons de taxas de juros (RWAJUR4) | E12: 0
C13: 2 | D13: Preços de ações (RWAacs) | E13: 0
C14: 3 | D14: Taxas de câmbio (RWAcam) | E14: 98924161
C15: 4 | D15: Preços de mercadorias (commodities) (RWAcom) | E15: 0
C16: 9 | D16: Total | E16: 3.7046848e+08
C18: Comentários

Sheet CR1
E4: a | F4: b | G4: c | H4: g
C5: Qualidade creditícia das exposições [CR1] | E5: Dec-22
E6: Valor bruto | G6: Provisões, adiantamentos e rendas a apropriar | H6: Valor líquido (a+b-c)
C7: Valores em R$ | E7: Exposições caracterizadas como operações em curso anormal | F7: Em curso normal
C8: 1 | D8: Concessão de crédito | E8: 4547389 | F8: =31529124-1 -> 31529123 | G8: 6698235 | H8: =sum(E8:F8)-G8 -> 29378277
C9: 2 | D9: Títulos de dívida | F9: 32107799 | H9: =sum(E9:F9)-G9 -> 32107799
C10: 2a | D10: dos quais: títulos soberanos nacionais | F10: 31254726 | H10: =sum(E10:F10)-G10 -> 31254726
C11: 2b | D11: dos quais: outros títulos | F11: 853073 | H11: =sum(E11:F11)-G11 -> 853073
C12: 3 | D12: Operações não contabilizadas no balanço patrimonial | F12: 233404 | H12: =sum(E12:F12)-G12 -> 233404
C13: 4 | D13: Total (1+2+3) | E13: =sum(E8,E9,E12) -> 4547389 | F13: =sum(F8,F9,F12) -> 63870326 | G13: =sum(G8,G9,G12) -> 6698235 | H13: =sum(E13:F13)-G13 -> 61719480
C15: Comentários

Sheet CR2
C5: Qualidade creditícia das exposições [CR2]
E6: a
C7: Valores em R$ | E7: 44926
C8: 1 | D8: Valor das operações em curso anormal no final do período anterior | E8: 2689376
C9: 2 | D9: Valor das operações que passaram a ser classificadas como em curso anormal no período corrente | E9: 3280321
C10: 3 | D10: Valor das operações reclassificadas para curso normal | E10: -76744
C11: 4 | D11: Valor da baixa contábil por prejuízo | E11: -1258602
C12: 5 | D12: Outros ajustes | E12: -86962
C13: 6 | D13: Valor das operações em curso anormal no final do período corrente (1+2+3+4+5) | E13: =sum(E8:E12) -> 4547389
C15: Comentários

Sheet CRBa
C5: Total de Exposições por região geográfica, setor econômico e prazo remanescente de vencimento
C7: Valores em R$ mil | E7: 44926
C10: Exposições por região geográfica
D11: Centro-Oeste | E11: 1569788
D12: Nordeste | E12: 3006364
D13: Norte | E13: 964520
D14: Sudeste | E14: 7168108
D15: Sul | E15: 17755991
D16: Território Nacional | E16: 31254709
D18: Total | E18: =sum(E11:E16) -> 61719480
C20: Exposições por setor econômico
D21: Pessoa Física | E21: 14288073
D22: Pessoa Jurídica | E22: =sum(E23:E26) -> 47431407
D23: Indústria | E23: =212760-1 -> 212759
D24: Comércio | E24: 3875
D25: Serviços | E25: 15960064
D26: Titulos Soberanos | E26: 31254709
D28: Total | E28: =sum(E22,E21) -> 61719480
C30: Exposições por prazo remanescente de vencimento
D31: Até 6 meses | E31: 14833004
D32: De 6 meses a 1 ano | E32: 12160187
D33: Acima de 1 ano | E33: 34726289
D35: Total | E35: 61719480
C37: Comentários
D38: Exposições em Território Nacional correspondem a Títulos Soberanos

Sheet CRBb
C5: Total de Exposições em curso anormal por região geográfica e setor econômico
C7: Valores em R$ mil | G7: 44926
E9: Carteira Curso Anormal | F9: Provisão | G9: Baixas/Prejuízos
C10: Exposições por região geográfica
D11: Centro-Oeste | E11: 442955 | F11: 373888 | G11: 179476
D12: Nordeste | E12: 1075472 | F12: 889358 | G12: 578159
D13: Norte | E13: 257903 | F13: 218175 | G13: 96030
D14: Sudeste | E14: 2128779 | F14: 1778618 | G14: 960918
D15: Sul | E15: 642280 | F15: 540799 | G15: 250345
D17: Total | E17: =sum(E11:E15) -> 4547389 | F17: =sum(F11:F15) -> 3800838 | G17: =sum(G11:G15) -> 2064928
C19: Exposições por setor econômico
D20: Pessoa Física | E20: 4534734 | F20: 3790654 | G20: 2064339
D21: Pessoa Jurídica | E21: =sum(E22:E24) -> 12655 | F21: =sum(F22:F24) -> 10184 | G21: =sum(G22:G24) -> 590
D22: Indústria | E22: =1130+1 -> 1131 | F22: 907 | G22: 44
D23: Comércio | E23: 4903 | F23: 3952 | G23: 251
D24: Serviços | E24: 6621 | F24: 5325 | G24: 295
D26: Total | E26: =sum(E20,E21) -> 4547389 | F26: =sum(F20,F21) -> 3800838 | G26: =sum(G20,G21) -> 2064929
C29: Comentários
C31: Operações em curso anormal classificadas conforme Resolução nº 54, Art. 11 § 3º

Sheet CRBc
C5: Total de Exposições segmentadas por faixas de atraso
C7: Valores em R$ mil | E7: 44926
C10: Exposições por faixa de atraso
D11: Menor que 30 dias | E11: 1539701
D12: de 31 a 90 dias | E12: 1383301
D13: de 91 a 180 dias | E13: 1688214
D14: de 181 a 365 dias | E14: 2428949
D16: Total | E16: =sum(E11:E14) -> 7040165

Sheet CRBd
C5: Total de Exposições reestruturadas, em curso anormal e demais
C7: Valores em R$ mil | E7: 44926
C10: Operações Reestruturadas
D11: Em curso anormal | E11: 570271.8
D12: Demais | E12: 18593.8
D13: Total | E13: 588865.6
C17: Comentários
C19: Operações reestruturadas classificadas conforme Resolução nº 4557, Art. 21 § 1º Inc. II
C20: Operações em curso anormal classificadas conforme Resolução nº 54, Art. 11 § 3º

Sheet CRBe
C5: Percentual das dez e cem maiores exposições em relação ao total
C7: Valores em % | E7: 44926
C10: Concentração de Exposições
D11: 10 maiores devedores | E11: 0.7622
D12: 100 maiores devedores | E12: 76.84%
C16: Comentários
C18: Inclui exposições a títulos de dívidas soberanos

Sheet IRRBB1
C5: Informações quantitativas sobre o IRRBB [IRRBB1]
E6: ΔEVE | G6: ΔNII
C7: Valores em R$ | E7: 44926 | F7: 44561 | G7: 44926 | H7: 44561
D8: Cenário paralelo de alta | E8: 65333 | F8: 27374 | G8: 74091 | H8: 30606
D9: Cenário paralelo de baixa | E9: 191041598 | F9: - | G9: 677583105 | H9: 208388039
D10: Cenário de aumento das taxas de juros de curto prazo
D11: Cenário de redução das taxas de juros de curto prazo
D12: Cenário steepener
D13: Cenário flattener
D14: Variação máxima | E14: 191041598 | F14: 27374 | G14: 677583105 | H14: 208388039
D15: Data-base | E15: 44926 | G15: 44561
D16: Nível I do Patrimônio de Referência (PR) | E16: 4782890907 | G16: 2605153847
C18: Comentários

Sheet Exposição Derivativos
C5: Informações quantitativas sobre a exposição associada a instrumentos financeiros derivativos
C6: Derivativos: Carteira de Negociação e Carteira Bancária
C7: Em R$ milhões | K7: 44926
D8: Com contraparte central | H8: Sem contraparte central
D9: Brasil | F9: Exterior | H9: Brasil | J9: Exterior
C10: Fatores de Risco | D10: Comprada | E10: Vendida | F10: Comprada | G10: Vendida | H10: Comprada | I10: Vendida | J10: Comprada | K10: Vendida
C11: Taxas de Juros | D11: 50 | E11: 10566 | F11: 0 | G11: 0 | H11: 143 | I11: 0 | J11: 0 | K11: 0
C12: Taxas de Câmbio | D12: 36 | E12: 0 | F12: 0 | G12: 0 | H12: 0 | I12: 0 | J12: 0 | K12: 0
C13: Ações | D13: 0 | E13: 0 | F13: 0 | G13: 0 | H13: 0 | I13: 0 | J13: 0 | K13: 0
C14: Commodities | D14: 0 | E14: 0 | F14: 0 | G14: 0 | H14: 0 | I14: 0 | J14: 0 | K14: 0

Sheet Padrão
A1: Table Name | B1: Reference Date | C1: Table Description | D1: Topic | E1: Line | F1: Line Description | G1: A | H1: B | I1: C | J1: D | K1: E | L1: F | M1: G | N1: H | O1: C_1 | P1: C_2 | Q1: Comments
A2: CCA | B2: 2022-1 | C2: Principais características dos instrumentos que compõem o Patrimônio de Referência (PR) | E2: 1 | F2: Emissor | G2: =CCA!E8 -> NU FINANCEIRA S.A. – SOCIEDADE DE CRÉDITO, FINANCIAMENTO E INVESTIMENTO | H2: =CCA!F8 -> NU FINANCEIRA S.A. – SOCIEDADE DE CRÉDITO, FINANCIAMENTO E INVESTIMENTO
A3: CCA | B3: 2022-1 | C3: Principais características dos instrumentos que compõem o Patrimônio de Referência (PR) | E3: 2 | F3: Identificador único | G3: =CCA!E9 -> LFSN1900844 | H3: =CCA!F9 -> LFSN22008CB
A4: CCA | B4: 2022-1 | C4: Principais características dos instrumentos que compõem o Patrimônio de Referência (PR) | E4: 3 | F4: Lei aplicável ao instrumento | G4: =CCA!E10 -> Lei nº 12.249, de 11 de junho de 2010 |Resolução nº 4.123, de 23 de agosto de 2012, do Conselho Monetário Nacional | Resolução nº 4.192, de 1º de março de 2013, do CMN | Lei nº 6.385, de 7 de dezembro de 1976 | Instrução CVM nº 476, de 16 de janeiro de 2009 | H4: =CCA!F10 -> Lei nº 12.249, de 11 de junho de 2010 |Resolução nº 4.123, de 23 de agosto de 2012, do Conselho Monetário Nacional | Resolução nº 4.192, de 1º de março de 2013, do CMN | Lei nº 6.385, de 7 de dezembro de 1976 | Instrução CVM nº 476, de 16 de janeiro de 2009
A5: CCA | B5: 2022-1 | C5: Principais características dos instrumentos que compõem o Patrimônio de Referência (PR) | E5: 4 | F5: Classificação do instrumento como componente do PR durante o tratamento temporário de que trata o art. 28 da Resolução nº 4.192, de 2013. | G5: =CCA!E11 -> NA | H5: =CCA!F11 -> NA
A6: CCA | B6: 2022-1 | C6: Principais características dos instrumentos que compõem o Patrimônio de Referência (PR) | E6: 5 | F6: Classificação do instrumento como componente do PR após o tratamento temporário de que trata a linha anterior | G6: =CCA!E12 -> Nível II | H6: =CCA!F12 -> Nível II
A7: CCA | B7: 2022-1 | C7: Principais características dos instrumentos que compõem o Patrimônio de Referência (PR) | E7: 6 | F7: Escopo da elegibilidade do instrumento | G7: =CCA!E13 -> Conglomerado | H7: =CCA!F13 -> Conglomerado
A8: CCA | B8: 2022-1 | C8: Principais características dos instrumentos que compõem o Patrimônio de Referência (PR) | E8: 7 | F8: Tipo de instrumento | G8: =CCA!E14 -> Letra Financeira | H8: =CCA!F14 -> Letra Financeira
A9: CCA | B9: 2022-1 | C9: Principais características dos instrumentos que compõem o Patrimônio de Referência (PR) | E9: 8 | F9: Valor reconhecido no PR | G9: =CCA!E15 -> 1.1487324e+08 | H9: =CCA!F15 -> 8.6671605e+08
A10: CCA | B10: 2022-1 | C10: Principais características dos instrumentos que compõem o Patrimônio de Referência (PR) | E10: 9 | F10: Valor de face do instrumento | G10: =CCA!E16 -> 75000000 | H10: =CCA!F16 -> 800000000
A11: CCA | B11: 2022-1 | C11: Principais características dos instrumentos que compõem o Patrimônio de Referência (PR) | E11: 10 | F11: Classificação contábil | G11: =CCA!E17 -> Passivo – custo amortizado | H11: =CCA!F17 -> Passivo – custo amortizado
A12: CCA | B12: 2022-1 | C12: Principais características dos instrumentos que compõem o Patrimônio de Referência (PR) | E12: 11 | F12: Data original de emissão | G12: =CCA!E18 -> 14/06/19 | H12: =CCA!F18 -> 17/06/22
A13: CCA | B13: 2022-1 | C13: Principais características dos instrumentos que compõem o Patrimônio de Referência (PR) | E13: 12 | F13: Perpétuo ou com vencimento | G13: =CCA!E19 -> Com vencimento | H13: =CCA!F19 -> Com vencimento
... A17: CCA | B17: 2022-1 | C17: Principais características dos instrumentos que compõem o Patrimônio de Referência (PR) | E17: 16 | F17: Datas de resgate ou de recompra subsequentes, se aplicável | G17: =CCA!E23 -> Resgate ou recompra pode ocorrer a partir 14/06/2024 | H17: =CCA!F23 -> Resgate ou recompra pode ocorrer a partir 17/06/2027
A18: CCA | B18: 2022-1 | C18: Principais características dos instrumentos que compõem o Patrimônio de Referência (PR) | D18: Remuneração/Dividendos | E18: 17 | F18: Remuneração ou dividendos fixos ou variáveis | G18: =CCA!E26 -> 12,8% | H18: =CCA!F26 -> 16,0%
A19: CCA | B19: 2022-1 | C19: Principais características dos instrumentos que compõem o Patrimônio de Referência (PR) | D19: Remuneração/Dividendos | E19: 18 | F19: Taxa de remuneração e índice referenciado | G19: =CCA!E27 -> Não | H19: =CCA!F27 -> Não
A20: CCA | B20: 2022-1 | C20: Principais características dos instrumentos que compõem o Patrimônio de Referência (PR) | D20: Remuneração/Dividendos | E20: 19 | F20: Possibilidade de suspensão de pagamento de dividendos | G20: =CCA!E28 -> Mandatório | H20: =CCA!F28 -> Mandatório
A21: CCA | B21: 2022-1 | C21: Principais características dos instrumentos que compõem o Patrimônio de Referência (PR) | D21: Remuneração/Dividendos | E21: 20 | F21: Completa discricionariedade, discricionariedade parcial ou mandatória | G21: =CCA!E29 -> Não | H21: =CCA!F29 -> Não
A22: CCA | B22: 2022-1 | C22: Principais características dos instrumentos que compõem o Patrimônio de Referência (PR) | D22: Remuneração/Dividendos | E22: 21 | F22: Existência de cláusulas que alterem prazos ou condições de remuneração pactuados ou outro incentivo para resgate | G22: =CCA!E30 -> NA | H22: =CCA!F30 -> NA
A23: CCA | B23: 2022-1 | C23: Principais características dos instrumentos que compõem o Patrimônio de Referência (PR) | D23: Remuneração/Dividendos | E23: 22 | F23: Cumulativo ou não cumulativo | G23: =CCA!E31 -> Não conversível | H23: =CCA!F31 -> Não conversível
A24: CCA | B24: 2022-1 | C24: Principais características dos instrumentos que compõem o Patrimônio de Referência (PR) | D24: Remuneração/Dividendos | E24: 23 | F24: Conversível ou não conversível | G24: =CCA!E32 -> NA | H24: =CCA!F32 -> NA
A25: CCA | B25: 2022-1 | C25: Principais características dos instrumentos que compõem o Patrimônio de Referência (PR) | D25: Remuneração/Dividendos | E25: 24 | F25: Se conversível, em quais situações | G25: =CCA!E33 -> NA | H25: =CCA!F33 -> NA
A26: CCA | B26: 2022-1 | C26: Principais características dos instrumentos que compõem o Patrimônio de Referência (PR) | D26: Remuneração/Dividendos | E26: 25 | F26: Se conversível, totalmente ou parcialmente | G26: =CCA!E34 -> NA | H26: =CCA!F34 -> NA
A27: CCA | B27: 2022-1 | C27: Principais características dos instrumentos que compõem o Patrimônio de Referência (PR) | D27: Remuneração/Dividendos | E27: 26 | F27: Se conversível, taxa de conversão | G27: =CCA!E35 -> NA | H27: =CCA!F35 -> NA
A28: CCA | B28: 2022-1 | C28: Principais características dos instrumentos que compõem o Patrimônio de Referência (PR) | D28: Remuneração/Dividendos | E28: 27 | F28: Se conversível, conversão obrigatória ou opcional | G28: =CCA!E36 -> NA | H28: =CCA!F36 -> NA
A29: CCA | B29: 2022-1 | C29: Principais características dos instrumentos que compõem o Patrimônio de Referência (PR) | D29: Remuneração/Dividendos | E29: 28 | F29: Se conversível, especificar para qual tipo de instrumento | G29: =CCA!E37 -> NA | H29: =CCA!F37 -> NA
... A37: CCA | B37: 2022-1 | C37: Principais características dos instrumentos que compõem o Patrimônio de Referência (PR) | D37: Remuneração/Dividendos | E37: 36 | F37: Possui características que não serão aceitas após o tratamento temporário de que trata o art. 28 da Resolução nº 4.192, de 2013 | G37: =CCA!E45 -> NA | H37: =CCA!F45 -> NA
A38: CCA | B38: 2022-1 | C38: Principais características dos instrumentos que compõem o Patrimônio de Referência (PR) | D38: Remuneração/Dividendos | E38: 37 | F38: Se sim, especificar as características de que trata a linha anterior | G38: =#REF! -> #REF! | H38: =#REF! -> #REF!
A39: CC1 | B39: 2022-1 | C39: Composição do Patrimônio de Referência (PR) | D39: Capital Principal: instrumentos e reservas | E39: 1 | F39: Instrumentos elegíveis ao Capital Principal | G39: ='CC1'!E9 -> 4008404593
A40: CC1 | B40: 2022-1 | C40: Composição do Patrimônio de Referência (PR) | D40: Capital Principal: instrumentos e reservas | E40: 2 | F40: Reservas de lucros | G40: ='CC1'!E10 -> 1406949153
A41: CC1 | B41: 2022-1 | C41: Composição do Patrimônio de Referência (PR) | D41: Capital Principal: instrumentos e reservas | E41: 3 | F41: Outras receitas e outras reservas | G41: ='CC1'!E11 -> 87924176
A42: CC1 | B42: 2022-1 | C42: Composição do Patrimônio de Referência (PR) | D42: Capital Principal: instrumentos e reservas | E42: 5 | F42: Participação de não controladores nos instrumentos emitidos por subsidiárias do conglomerado prudencial e elegíveis ao seu Capital Principal | G42: ='CC1'!E12 -> -
A43: CC1 | B43: 2022-1 | C43: Composição do Patrimônio de Referência (PR) | D43: Capital Principal: instrumentos e reservas | E43: 6 | F43: Capital Principal antes dos ajustes prudenciais | G43: ='CC1'!E13 -> 5503277922
A44: CC1 | B44: 2022-1 | C44: Composição do Patrimônio de Referência (PR) | D44: Capital Principal: ajustes prudenciais | E44: 7 | F44: Ajustes prudenciais relativos a apreçamentos de instrumentos financeiros (PVA) | G44: ='CC1'!E15 -> -
A45: CC1 | B45: 2022-1 | C45: Composição do Patrimônio de Referência (PR) | D45: Capital Principal: ajustes prudenciais | E45: 8 | F45: Ágios pagos na aquisição de investimentos com fundamento em expectativa de rentabilidade futura | G45: ='CC1'!E16 -> 1054082014
A46: CC1 | B46: 2022-1 | C46: Composição do Patrimônio de Referência (PR) | D46: Capital Principal: ajustes prudenciais | E46: 9 | F46: Ativos intangíveis | G46: ='CC1'!E17 -> 2.97501e+08
A47: CC1 | B47: 2022-1 | C47: Composição do Patrimônio de Referência (PR) | D47: Capital Principal: ajustes prudenciais | E47: 10 | F47: Créditos tributários decorrentes de prejuízos fiscais e de base negativa de Contribuição Social sobre o Lucro Líquido e os originados dessa contribuição relativos a períodos de apuração encerrados até 31 de dezembro de 1998 | G47: ='CC1'!E18 -> 87690035
A48: CC1 | B48: 2022-1 | C48: Composição do Patrimônio de Referência (PR) | D48: Capital Principal: ajustes prudenciais | E48: 11 | F48: Ajustes relativos ao valor de mercado dos instrumentos financeiros derivativos utilizados para hedge de fluxo de caixa de itens protegidos cujos ajustes de marcação a mercado não são registrados contabilmente | G48: ='CC1'!E19 -> -
A49: CC1 | B49: 2022-1 | C49: Composição do Patrimônio de Referência (PR) | D49: Capital Principal: ajustes prudenciais | E49: 15 | F49: Ativos atuariais relacionados a fundos de pensão de benefício definido | G49: ='CC1'!E20 -> -
A50: CC1 | B50: 2022-1 | C50: Composição do Patrimônio de Referência (PR) | D50: Capital Principal: ajustes prudenciais | E50: 16 | F50: Ações ou outros instrumentos de emissão própria autorizados a compor o Capital Principal da instituição ou conglomerado, adquiridos diretamente, indiretamente ou de forma sintética | G50: ='CC1'!E21 -> -
...

Sheet Campos Adicionais
A1: Table Name | B1: Reference Date | C1: Table Description | D1: Topic | E1: Line | F1: Line Description | G1: Name | H1: Description | I1: Value
A2: CC2 | B2: 2022-8 | C2: Conciliação do Patrimônio de Referência (PR) com o balanço patrimonial | D2: Ativos | E2: 11 | F2: Total de ativos | G2: A | H2: Aplicações Interfinanceiras de Liquidez | I2: ='CC2'!E10 -> 3.1399741e+08
A3: CC2 | B3: 2022-8 | C3: Conciliação do Patrimônio de Referência (PR) com o balanço patrimonial | D3: Ativos | E3: 11 | F3: Total de ativos | G3: B | H3: Aplicações Interfinanceiras de Liquidez | I3: ='CC2'!F10 -> 3.1399741e+08
A4: CC2 | B4: 2022-8 | C4: Conciliação do Patrimônio de Referência (PR) com o balanço patrimonial | D4: Ativos | E4: 11 | F4: Total de ativos | G4: A | H4: Operações de crédito | I4: ='CC2'!E12 -> 20058591809
A5: CC2 | B5: 2022-8 | C5: Conciliação do Patrimônio de Referência (PR) com o balanço patrimonial | D5: Ativos | E5: 11 | F5: Total de ativos | G5: B | H5: Operações de crédito | I5: ='CC2'!F12 -> 20058591809
A6: CC2 | B6: 2022-8 | C6: Conciliação do Patrimônio de Referência (PR) com o balanço patrimonial | D6: Ativos | E6: 11 | F6: Total de ativos | G6: A | H6: Outros créditos | I6: ='CC2'!E26 -> 7047363175
A7: CC2 | B7: 2022-8 | C7: Conciliação do Patrimônio de Referência (PR) com o balanço patrimonial | D7: Ativos | E7: 11 | F7: Total de ativos | G7: B | H7: Outros créditos | I7: ='CC2'!F26 -> 7047363175
A8: CC2 | B8: 2022-8 | C8: Conciliação do Patrimônio de Referência (PR) com o balanço patrimonial | D8: Ativos | E8: 11 | F8: Total de ativos | G8: A | H8: Ágio baseado em expectativa de rentabilidade futura | I8: ='CC2'!E19 -> -
A9: CC2 | B9: 2022-8 | C9: Conciliação do Patrimônio de Referência (PR) com o balanço patrimonial | D9: Ativos | E9: 11 | F9: Total de ativos | G9: B | H9: Ágio baseado em expectativa de rentabilidade futura | I9: ='CC2'!F19 -> -
A10: CC2 | B10: 2022-8 | C10: Conciliação do Patrimônio de Referência (PR) com o balanço patrimonial | D10: Ativos | E10: 11 | F10: Total de ativos | G10: A | H10: Participação em Instituições Financeiras | I10: ='CC2'!E20 -> -
A11: CC2 | B11: 2022-8 | C11: Conciliação do Patrimônio de Referência (PR) com o balanço patrimonial | D11: Ativos | E11: 11 | F11: Total de ativos | G11: B | H11: Participação em Instituições Financeiras | I11: ='CC2'!F20 -> -
A12: CC2 | B12: 2022-8 | C12: Conciliação do Patrimônio de Referência (PR) com o balanço patrimonial | D12: Ativos | E12: 11 | F12: Total de ativos | G12: A | H12: Outros | I12: ='CC2'!E21 -> 1.0609776e+08
A13: CC2 | B13: 2022-8 | C13: Conciliação do Patrimônio de Referência (PR) com o balanço patrimonial | D13: Ativos | E13: 11 | F13: Total de ativos | G13: B | H13: Outros | I13: ='CC2'!F21 -> 1.0609776e+08
A14: CC2 | B14: 2022-8 | C14: Conciliação do Patrimônio de Referência (PR) com o balanço patrimonial | D14: Ativos | E14: 11 | F14: Total de ativos | G14: A | H14: Ativos Fiscais | I14: ='CC2'!E17 -> 2282926592
A15: CC2 | B15: 2022-8 | C15: Conciliação do Patrimônio de Referência (PR) com o balanço patrimonial | D15: Ativos | E15: 11 | F15: Total de ativos | G15: B | H15: Ativos Fiscais | I15: ='CC2'!F17 -> 2282926592
A16: CC2 | B16: 2022-8 | C16: Conciliação do Patrimônio de Referência (PR) com o balanço patrimonial | D16: Ativos | E16: 11 | F16: Total de ativos | G16: A | H16: Corrente | I16: ='CC2'!E16 -> -
A17: CC2 | B17: 2022-8 | C17: Conciliação do Patrimônio de Referência (PR) com o balanço patrimonial | D17: Ativos | E17: 11 | F17: Total de ativos | G17: B | H17: Corrente | I17: ='CC2'!F16 -> -
A18: CC2 | B18: 2022-8 | C18: Conciliação do Patrimônio de Referência (PR) com o balanço patrimonial | D18: Passivos | E18: 15 | F18: Total de passivos | G18: A | H18: Outras obrigações | I18: ='CC2'!E34 -> 7378034244
A19: CC2 | B19: 2022-8 | C19: Conciliação do Patrimônio de Referência (PR) com o balanço patrimonial | D19: Passivos | E19: 15 | F19: Total de passivos | G19: B | H19: Outras obrigações | I19: ='CC2'!F34 -> 7378034244
A20: CC2 | B20: 2022-8 | C20: Conciliação do Patrimônio de Referência (PR) com o balanço patrimonial | D20: Passivos | E20: 15 | F20: Total de passivos | G20: A | H20: Obrigações Fiscais | I20: ='CC2'!E33 -> 28991690
A21: CC2 | B21: 2022-8 | C21: Conciliação do Patrimônio de Referência (PR) com o balanço patrimonial | D21: Passivos | E21: 15 | F21: Total de passivos | G21: B | H21: Obrigações Fiscais | I21: ='CC2'!F33 -> 28991690
A22: CC2 | B22: 2022-8 | C22: Conciliação do Patrimônio de Referência (PR) com o balanço patrimonial | D22: Passivos | E22: 15 | F22: Total de passivos | G22: A | H22: Corrente | I22: ='CC2'!E32 -> 2498152630
A23: CC2 | B23: 2022-8 | C23: Conciliação do Patrimônio de Referência (PR) com o balanço patrimonial | D23: Passivos | E23: 15 | F23: Total de passivos | G23: B | H23: Corrente | I23: ='CC2'!F32 -> 2498152630
